Workbook

Sheet Dashboard
A1: 💰 MY FINANCE DASHBOARD
A2: Auto-calculated from your Weekly & Monthly Planner sheets
A4: 📊 MONTHLY OVERVIEW
A5: Category | B5: Budgeted (₵) | C5: Actual (₵) | D5: Difference (₵) | E5: % Used | F5: Status
A6: Total Income | B6: ='Monthly Planner'!C9 | C6: ='Monthly Planner'!D9 | D6: =B6-C6 | E6: =IFERROR(C6/B6,0) | F6: =IF(D6>=0,"✔ On Track","✘ Over Budget")
A7: Essential Expenses | B7: ='Monthly Planner'!C19 | C7: ='Monthly Planner'!D19 | D7: =B7-C7 | E7: =IFERROR(C7/B7,0) | F7: =IF(D7>=0,"✔ On Track","✘ Over Budget")
A8: Lifestyle Expenses | B8: ='Monthly Planner'!C27 | C8: ='Monthly Planner'!D27 | D8: =B8-C8 | E8: =IFERROR(C8/B8,0) | F8: =IF(D8>=0,"✔ On Track","✘ Over Budget")
A9: Savings | B9: 3500 | C9: ='Monthly Planner'!D34 | D9: =B9-C9 | E9: =IFERROR(C9/B9,0) | F9: =IF(D9>=0,"✔ On Track","✘ Over Budget")
A10: NET BALANCE | B10: =B6-B7-B8-B9 | C10: ='Monthly Planner'!D30 | D10: =B10-C10 | E10: =IFERROR(C10/B10,0) | F10: =IF(D10>=0,"✔ On Track","✘ Over Budget")
A12: 🎯 SAVINGS GOAL TRACKER
A13: Goal | B13: Target (₵) | C13: Saved So Far (₵) | D13: Monthly Surplus (₵) | E13: Months to Goal | F13: Progress
A14: 100,000 Cedis Savings | B14: 25000 | C14: ='Monthly Planner'!D34 | D14: ='Monthly Planner'!D30 | E14: =IFERROR(IF(D14>0,CEILING((B14-C14)/D14,1),"Add surplus"),"—") | F14: =IFERROR(TEXT(C14/B14,"0%")&" complete","0% complete")
A16: 💡 QUICK TIPS
A17: ✅ Aim for 20%+ of income going to savings each month.
A18: ✅ Keep essential expenses below 60% of your income.
A19: ✅ Update your Weekly Planner every Sunday evening.
A20: ✅ Update your Monthly Planner on the 1st of each month.
A21: ✅ Reduce lifestyle spending first when you need to save more.

Sheet Monthly Planner
A1: 📅 MONTHLY FINANCE PLANNER
A2: Month: | B2: 46174 | D2: ← Update month each month
A3: Category | B3: Date | C3: Budget (₵) | D3: Actual (₵) | E3: Difference (₵) | F3: Notes
A4: INCOME
A5: Main job / salary | B5: 25th April 2026 | C5: 9000 | E5: =C5-D5
A6: Freelance income | E6: =C6-D6
A7: Side hustle | B7: Ongoing | C7: 25000 | E7: =C7-D7
A8: Other income | B8: Ongoing | E8: =C8-D8
A9: TOTAL INCOME | C9: =SUM(C5:C8) | D9: =D5+D6+D7+D8 | E9: =C9-D9
A11: ESSENTIAL EXPENSES
A12: Family | E12: =C12-D12
A13: Food & groceries | E13: =C13-D13
A14: Transport / fuel | E14: =C14-D14
A15: Utilities (light, water) | E15: =C15-D15
A16: Data & phone bill | E16: =C16-D16
A17: Medical / health/Gym | E17: =C17-D17 | F17: Insurance
A18: Tracker | E18: =C18-D18
A19: TOTAL ESSENTIALS | C19: =SUM(C12:C18) | D19: =SUM(D12:D18) | E19: =C19-D19
A21: LIFESTYLE EXPENSES (reduce these to save more)
A22: GIFT (Unplanned Expenses | E22: =C22-D22
A23: Eating out / takeaway | E23: =C23-D23
A24: Clothing & shopping | E24: =C24-D24
A25: Personal care | E25: =C25-D25
A26: Subscriptions/Transcript | E26: =C26-D26
A27: TOTAL LIFESTYLE | C27: =SUM(C22:C26) | D27: =SUM(D22:D26) | E27: =C27-D27
A28: Total Expense | C28: =C19+C27 | D28: =D19+D27 | E28: =E19+E27
A29: SAVINGS & INVESTMENTS
A30: Loaned to People | E30: =C30-D30
A31: Cedis goal | E31: =C31-D31
A32: Investment / stocks | E32: =C32-D32
A33: Business fund | E33: =C33-D33
A34: TOTAL SAVINGS | C34: =SUM(C30:C33) | D34: =SUM(D30:D33) | E34: =C34-D34
D35: =D9-D19-D27-D34
A36: NET BALANCE | C36: =C9-C19-C27-C34 | D36: =D9-D19-D27-D34 | E36: =C36-D36 | F36: =IF(D36>0,"✔ Surplus — good job!",IF(D36=0,"⚠ Break even","✘ Deficit — cut spending"))
A37: Savings rate (actual): | C37: =IFERROR(D34/D9,0) | F37: =IF(C37>=0.2,"✔ Great — above 20%",IF(C37>=0.1,"⚠ Aim for 20%","✘ Below 10% — increase savings"))
A39: COLOR KEY
A40: Blue numbers = enter your values here | C40: Black numbers = auto-calculated (do not edit)
B45: Budget (₵) | C45: Actual (₵)
A46: INCOME | B46: =600+400
A47: EXPENSE | B47: =300
...

Sheet Weekly 1 Planner
A1: 📆 WEEKLY FINANCE PLANNER | J1: WEEKLY FINANCE PLANNER
A2: Week of: 1 | B2: 21 Apr 2026 | D2: ← Update each week | J2: Week of: 1 | K2: 46132 | M2: ← Update each week
A3: Category | B3: Mon | C3: Tue | D3: Wed | E3: Thu | F3: Fri | G3: Sat | H3: Sun | I3: Weekly Total | J3: Category | K3: Mon | L3: Tue | M3: Wed | N3: Thu | O3: Fri | P3: Sat | Q3: Sun | R3: Weekly Total
A4: INCOME THIS WEEK | J4: INCOME THIS WEEK
A5: Salary / wages | B5: 0 | C5: 0 | D5: 0 | E5: 0 | F5: 0 | G5: 0 | H5: 0 | I5: =SUM(B5:H5) | J5: Salary / wages | K5: 0 | L5: 0 | M5: 0 | N5: 0 | O5: 0 | P5: 0 | Q5: 0 | R5: =SUM(K5:Q5)
A6: Freelance payment | B6: 0 | C6: 0 | D6: 0 | E6: 0 | F6: 0 | G6: 0 | H6: 0 | I6: =SUM(B6:H6) | J6: Freelance payment | K6: 0 | L6: 0 | M6: 0 | N6: 0 | O6: 0 | P6: 0 | Q6: 0 | R6: =SUM(K6:Q6)
A7: Other income | B7: 0 | C7: 0 | D7: 0 | E7: 0 | F7: 0 | G7: 0 | H7: 0 | I7: =SUM(B7:H7) | J7: Other income | L7: 0 | M7: 0 | N7: 0 | R7: =SUM(K7:Q7)
A8: TOTAL INCOME | B8: =SUM(B5:B7) | C8: =SUM(C5:C7) | D8: =SUM(D5:D7) | E8: =SUM(E5:E7) | F8: =SUM(F5:F7) | G8: =SUM(G5:G7) | H8: =SUM(H5:H7) | I8: =SUM(B8:H8) | J8: TOTAL INCOME | K8: =SUM(K5:K7) | L8: =SUM(L5:L7) | M8: =SUM(M5:M7) | N8: =SUM(N5:N7) | O8: =SUM(O5:O7) | P8: =SUM(P5:P7) | Q8: =SUM(Q5:Q7) | R8: =SUM(K8:Q8)
A10: DAILY EXPENSES | J10: DAILY EXPENSES
A11: Food & drinks | B11: 0 | C11: 0 | D11: 0 | E11: 0 | F11: 0 | G11: 0 | H11: 0 | I11: =SUM(B11:H11) | J11: Food & drinks | O11: 0 | P11: 0 | Q11: 0 | R11: =SUM(K11:Q11)
A12: Transport | B12: 25 | C12: 25 | D12: 25 | E12: 25 | G12: 0 | H12: 0 | I12: =SUM(B12:H12) | J12: Transport | P12: 0 | Q12: 0 | R12: =SUM(K12:Q12)
A13: Data / phone | B13: 20 | C13: 0 | D13: 0 | E13: 0 | F13: 0 | G13: 0 | H13: 0 | I13: =SUM(B13:H13) | J13: Data / phone | O13: 0 | P13: 0 | Q13: 0 | R13: =SUM(K13:Q13)
A14: Entertainment | B14: 0 | C14: 0 | D14: 0 | E14: 0 | F14: 0 | G14: 0 | H14: 0 | I14: =SUM(B14:H14) | J14: Entertainment | O14: 0 | P14: 0 | Q14: 0 | R14: =SUM(K14:Q14)
A15: Shopping | B15: 0 | C15: 0 | D15: 0 | E15: 0 | F15: 0 | G15: 0 | H15: 0 | I15: =SUM(B15:H15) | J15: Shopping | O15: 0 | P15: 0 | Q15: 0 | R15: =SUM(K15:Q15)
A16: Other | B16: 0 | C16: 0 | D16: 90 | E16: 0 | F16: 0 | G16: 0 | H16: 0 | I16: =SUM(B16:H16) | J16: Other | O16: 0 | P16: 0 | Q16: 0 | R16: =SUM(K16:Q16)
A17: TOTAL EXPENSES | B17: =SUM(B11:B16) | C17: =SUM(C11:C16) | D17: =SUM(D11:D16) | E17: =SUM(E11:E16) | F17: =SUM(F11:F16) | G17: =SUM(G11:G16) | H17: =SUM(H11:H16) | I17: =SUM(B17:H17) | J17: TOTAL EXPENSES | K17: =SUM(K11:K16) | L17: =SUM(L11:L16) | M17: =SUM(M11:M16) | N17: =SUM(N11:N16) | O17: =SUM(O11:O16) | P17: =SUM(P11:P16) | Q17: =SUM(Q11:Q16) | R17: =SUM(K17:Q17)
A19: WEEKLY NET BALANCE | I19: =I8-I17 | J19: WEEKLY NET BALANCE | R19: =R8-R17
A21: Daily spend total: | B21: =SUM(B11:B16) | C21: =SUM(C11:C16) | D21: =SUM(D11:D16) | E21: =SUM(E11:E16) | F21: =SUM(F11:F16) | G21: =SUM(G11:G16) | H21: =SUM(H11:H16) | I21: =SUM(B21:H21) | J21: Daily spend total: | K21: =SUM(K11:K16) | L21: =SUM(L11:L16) | M21: =SUM(M11:M16) | N21: =SUM(N11:N16) | O21: =SUM(O11:O16) | P21: =SUM(P11:P16) | Q21: =SUM(Q11:Q16) | R21: =SUM(K21:Q21)
A23: NOTES / REFLECTIONS THIS WEEK | J23: NOTES / REFLECTIONS THIS WEEK
A24: What did I overspend on? What can I cut next week? | J24: What did I overspend on? What can I cut next week?
J25: WEEKLY FINANCE PLANNER
J26: Week of: 2 | K26: 46139 | M26: ← Update each week
J27: Category | K27: Mon | L27: Tue | M27: Wed | N27: Thu | O27: Fri | P27: Sat | Q27: Sun | R27: Weekly Total
J28: INCOME THIS WEEK
J29: Salary / wages | K29: 0 | L29: 0 | M29: 0 | N29: 0 | O29: 0 | P29: 0 | Q29: 0 | R29: =SUM(K29:Q29)
J30: Freelance payment | K30: 0 | L30: 0 | M30: 0 | N30: 0 | O30: 0 | P30: 0 | Q30: 0 | R30: =SUM(K30:Q30)
J31: Other income | K31: 0 | L31: 0 | M31: 0 | N31: 0 | O31: 0 | P31: 0 | Q31: 0 | R31: =SUM(K31:Q31)
J32: TOTAL INCOME | K32: =SUM(K29:K31) | L32: =SUM(L29:L31) | M32: =SUM(M29:M31) | N32: =SUM(N29:N31) | O32: =SUM(O29:O31) | P32: =SUM(P29:P31) | Q32: =SUM(Q29:Q31) | R32: =SUM(K32:Q32)
J34: DAILY EXPENSES
J35: Food & drinks | N35: 0 | O35: 0 | P35: 0 | Q35: 0 | R35: =SUM(K35:Q35)
J36: Transport | P36: 0 | Q36: 0 | R36: =SUM(K36:Q36)
J37: Data / phone | N37: 0 | O37: 0 | P37: 0 | Q37: 0 | R37: =SUM(K37:Q37)
J38: Entertainment | N38: 0 | O38: 0 | P38: 0 | Q38: 0 | R38: =SUM(K38:Q38)
J39: Shopping | N39: 0 | O39: 0 | P39: 0 | Q39: 0 | R39: =SUM(K39:Q39)
J40: Other | N40: 0 | O40: 0 | P40: 0 | Q40: 0 | R40: =SUM(K40:Q40)
J41: TOTAL EXPENSES | K41: =SUM(K35:K40) | L41: =SUM(L35:L40) | M41: =SUM(M35:M40) | N41: =SUM(N35:N40) | O41: =SUM(O35:O40) | P41: =SUM(P35:P40) | Q41: =SUM(Q35:Q40) | R41: =SUM(K41:Q41)
J43: WEEKLY NET BALANCE | R43: =R32-R41
J45: Daily spend total: | K45: =SUM(K35:K40) | L45: =SUM(L35:L40) | M45: =SUM(M35:M40) | N45: =SUM(N35:N40) | O45: =SUM(O35:O40) | P45: =SUM(P35:P40) | Q45: =SUM(Q35:Q40) | R45: =SUM(K45:Q45)
J47: NOTES / REFLECTIONS THIS WEEK
J48: What did I overspend on? What can I cut next week?
...

Sheet Week 2 
A1: 📆 WEEKLY FINANCE PLANNER
A2: Week of: 1 | B2: 21 Apr 2026 | D2: ← Update each week
A3: Category | B3: Mon | C3: Tue | D3: Wed | E3: Thu | F3: Fri | G3: Sat | H3: Sun | I3: Weekly Total
A4: INCOME THIS WEEK
A5: Salary / wages | B5: 0 | C5: 0 | D5: 0 | E5: 0 | F5: 0 | G5: 0 | H5: 0 | I5: =SUM(B5:H5)
A6: Freelance payment | B6: 0 | C6: 0 | D6: 0 | E6: 0 | F6: 0 | G6: 0 | H6: 0 | I6: =SUM(B6:H6)
A7: Other income | B7: 0 | C7: 0 | D7: 0 | E7: 0 | F7: 0 | G7: 0 | H7: 0 | I7: =SUM(B7:H7)
A8: TOTAL INCOME | B8: =SUM(B5:B7) | C8: =SUM(C5:C7) | D8: =SUM(D5:D7) | E8: =SUM(E5:E7) | F8: =SUM(F5:F7) | G8: =SUM(G5:G7) | H8: =SUM(H5:H7) | I8: =SUM(B8:H8)
A10: DAILY EXPENSES
A11: Food & drinks | B11: 0 | C11: 0 | D11: 0 | E11: 0 | F11: 0 | G11: 0 | H11: 0 | I11: =SUM(B11:H11)
A12: Transport | F12: - | G12: 0 | H12: 0 | I12: =SUM(B12:H12)
A13: Data / phone | C13: 0 | D13: 0 | E13: 0 | F13: 0 | G13: 0 | H13: 0 | I13: =SUM(B13:H13)
A14: Entertainment | B14: 0 | C14: 0 | D14: 0 | E14: 0 | F14: 0 | G14: 0 | H14: 0 | I14: =SUM(B14:H14)
A15: Shopping | B15: 0 | C15: 0 | D15: 0 | E15: 0 | F15: 0 | G15: 0 | H15: 0 | I15: =SUM(B15:H15)
A16: Other | B16: 0 | C16: 0 | E16: 0 | F16: 0 | G16: 0 | H16: 0 | I16: =SUM(B16:H16)
A17: TOTAL EXPENSES | B17: =SUM(B11:B16) | C17: =SUM(C11:C16) | D17: =SUM(D11:D16) | E17: =SUM(E11:E16) | F17: =SUM(F11:F16) | G17: =SUM(G11:G16) | H17: =SUM(H11:H16) | I17: =SUM(B17:H17)
A19: WEEKLY NET BALANCE | I19: =I8-I17
A21: Daily spend total: | B21: =SUM(B11:B16) | C21: =SUM(C11:C16) | D21: =SUM(D11:D16) | E21: =SUM(E11:E16) | F21: =SUM(F11:F16) | G21: =SUM(G11:G16) | H21: =SUM(H11:H16) | I21: =SUM(B21:H21)
A23: NOTES / REFLECTIONS THIS WEEK
A24: What did I overspend on? What can I cut next week?

Sheet How To Use
A1: 📖 HOW TO USE THIS FINANCE PLANNER
A3: WEEKLY PLANNER
A4: 1. | B4: Go to the 'Weekly Planner' sheet every Sunday evening.
A5: 2. | B5: Update the 'Week of' date at the top.
A6: 3. | B6: Enter your daily spending in the correct category rows. Blue cells = your input.
A7: 4. | B7: The weekly total and net balance calculate automatically.
A8: 5. | B8: Write a note at the bottom — what did you overspend on?
A10: MONTHLY PLANNER
A11: 1. | B11: Go to the 'Monthly Planner' sheet on the 1st of each month.
A12: 2. | B12: Update the month name at the top.
A13: 3. | B13: Fill in the 'Budget' column (what you PLAN to spend).
A14: 4. | B14: Update the 'Actual' column throughout the month as you spend.
A15: 5. | B15: The Difference and Savings Rate calculate automatically.
A17: DASHBOARD
A18: 1. | B18: The Dashboard pulls data automatically from Monthly Planner.
A19: 2. | B19: Check it at any time to see your financial health at a glance.
A20: 3. | B20: Update the 'Saved So Far' cell in the goal tracker each month.
A22: COLOR KEY
A23: Blue | B23: Enter your numbers here (inputs)
A24: Black | B24: Auto-calculated — do not edit
A25: Green | B25: On track / surplus
A26: Red/Orange | B26: Over budget / needs attention
A28: YOUR GOAL
A29: Target: | B29: Save 100,000 cedis. Update your monthly surplus and watch the months-to-goal count down.
A30: Rule: | B30: Pay yourself first — set savings aside BEFORE spending on lifestyle.
A31: Rule: | B31: Keep lifestyle spending below 20% of income.
A32: Rule: | B32: Review every Sunday. Small consistent habits build big results.

Sheet Sheet2
